Workbook

Sheet Preliminary BOM
A1: Section | B1: Est. Qty | C1: Item | D1: Example / Value | E1: Notes | F1: Est. Unit Cost (USD) | G1: Est. Ext. Cost (USD) | H1: Suggested Source | I1: Candidate Part(s) | J1: Status / Action
A2: Power | B2: 1 | C2: 12 V input connector | D2: 2-pin terminal/header | E2: Main board power input | F2: 0.25 | G2: =B2*F2 -> 0.25 | H2: Digi-Key / Mouser / LCSC | I2: 2-pin 3.5mm screw terminal or 1x2 header | J2: Choose connector style based on enclosure/wiring
A3: Power | B3: 2 | C3: Resettable fuse | D3: Polyfuse/PTC | E3: Input overcurrent protection | F3: 0.35 | G3: =B3*F3 -> 0.7 | H3: Digi-Key / Mouser | I3: MF-LSMF050/72X, MF-LSMF075/72X | J3: Pick hold/trip current after load budget
A4: Power | B4: 1 | C4: TVS diode | D4: 12 V TVS | E4: Input transient/surge protection | F4: 0.3 | G4: =B4*F4 -> 0.3 | H4: Digi-Key / Mouser / LCSC | I4: 3KDFN15A or equivalent | J4: Confirm standoff/clamp voltage for 12V rail
A5: Power | B5: 1 | C5: PMOS reverse-polarity MOSFET | D5: P-channel MOSFET | E5: Protects board from reversed 12 V input | F5: 0.45 | G5: =B5*F5 -> 0.45 | H5: Digi-Key / Mouser | I5: DMP3098LSS or equivalent | J5: Confirm VDS, RDS(on), package/thermal
A6: Power | B6: 1 | C6: 12 V → 5 V buck regulator IC | D6: TPS62902 | E6: Generates 5 V rail | F6: 1.1 | G6: =B6*F6 -> 1.1 | H6: Digi-Key / Mouser / TI | I6: TPS62902 | J6: Confirm package/availability
A7: Power | B7: 1 | C7: 5 V → 3.3 V buck regulator IC | D7: TLV62569 | E7: Generates 3.3 V rail | F7: 0.6 | G7: =B7*F7 -> 0.6 | H7: Digi-Key / Mouser / TI | I7: TLV62569 | J7: Confirm package/availability
A8: Power | B8: 2 | C8: Power inductors | D8: 1 µH / 2.2 µH | E8: Buck regulator inductors | F8: 0.35 | G8: =B8*F8 -> 0.7 | H8: Digi-Key / Mouser / LCSC | I8: TBD shielded power inductor | J8: Must lock saturation current before layout
A9: Power | B9: 8 | C9: Buck regulator resistors | D9: Feedback/setpoint values | E9: Sets 5 V and 3.3 V outputs | F9: 0.02 | G9: =B9*F9 -> 0.16 | H9: Digi-Key / Mouser / LCSC | I9: 1% 0603/0805 resistors | J9: Verify exact values from regulator datasheets
A10: Power | B10: 6 | C10: Buck regulator capacitors | D10: 10 µF, 22 µF, 6.6 nF, etc. | E10: Input/output/soft-start/filter caps | F10: 0.08 | G10: =B10*F10 -> 0.48 | H10: Digi-Key / Mouser / LCSC | I10: X7R ceramics, voltage rating TBD | J10: Check DC bias derating and voltage rating
A11: Power | B11: 2 | C11: Rail indicator LEDs | D11: 5 V LED, 3.3 V LED | E11: Visual power indicators | F11: 0.05 | G11: =B11*F11 -> 0.1 | H11: Digi-Key / Mouser / LCSC | I11: Standard SMD LED | J11: Pick color/footprint
A12: Power | B12: 2 | C12: LED current-limiting resistors | D12: TBD | E12: For power LEDs | F12: 0.02 | G12: =B12*F12 -> 0.04 | H12: Digi-Key / Mouser / LCSC | I12: 0603/0805 resistor | J12: Set LED current target
A13: ESP32 / MCU | B13: 1 | C13: ESP32 module | D13: ESP32-WROOM-32E | E13: Main controller | F13: 3.5 | G13: =B13*F13 -> 3.5 | H13: Digi-Key / Mouser / LCSC / Espressif | I13: ESP32-WROOM-32E | J13: Lock exact module variant
... A47: PCB / Assembly | B47: 1 | C47: Bare PCB prototype | D47: 2-layer or 4-layer TBD | E47: Single-board bring-up prototype | F47: 10 | G47: =B47*F47 -> 10 | H47: JLCPCB / PCBWay / local fab | I47: Custom Rev 1 PCB | J47: Estimate only; depends on stackup/shipping
A49: Total | D49: Total | G49: =SUM(G2:G47) -> 32.28

Sheet Cost Summary
A1: Section | B1: Estimated Subtotal (USD) | D1: Notes
A2: Power | B2: =SUMIF('Preliminary BOM'!A:A,A2,'Preliminary BOM'!G:G) -> 4.88 | D2: Costs are rough prototype-level estimates only. They are not quoted prices and do not include tax, shipping, assembly labor, or quantity discounts. Final procurement BOM should be generated after footprints, package choices, and supplier availability are locked.
A3: ESP32 / MCU | B3: =SUMIF('Preliminary BOM'!A:A,A3,'Preliminary BOM'!G:G) -> 5.92
A4: Ethernet | B4: =SUMIF('Preliminary BOM'!A:A,A4,'Preliminary BOM'!G:G) -> 5.23
A5: Sensors | B5: =SUMIF('Preliminary BOM'!A:A,A5,'Preliminary BOM'!G:G) -> 1.45
A6: Off-board modules | B6: =SUMIF('Preliminary BOM'!A:A,A6,'Preliminary BOM'!G:G) -> 4.8
A7: PCB / Assembly | B7: =SUMIF('Preliminary BOM'!A:A,A7,'Preliminary BOM'!G:G) -> 10
A9: Estimated Prototype Subtotal | B9: =SUM(B2:B7) -> 32.28

Sheet Reference BOM
A1: Ref | B1: Sheet | C1: Value | D1: Footprint | E1: Description
A2: C1 | B2: Power | C2: 10uF | E2: Unpolarized capacitor, small symbol
A3: C2 | B3: Power | C3: 22 uF | E3: Unpolarized capacitor, small symbol
A4: C3 | B4: Power | C4: 6.6 nF | E4: Unpolarized capacitor, small symbol
A5: C4 | B5: Power | C5: 10 uF | E5: Unpolarized capacitor, small symbol
A6: C5 | B6: Power | C6: 10 uF | E6: Unpolarized capacitor, small symbol
A7: C6 | B7: Power | C7: 10 pF | E7: Unpolarized capacitor, small symbol
A8: D1 | B8: Power | C8: TVS Diode | D8: Diode_SMD:Nexperia_DSN1608-2_1.6x0.8mm | E8: 12V, 1900W TVS unidirectional diode, DSN1608-2
A9: D3 | B9: Power | C9: LED | E9: Light emitting diode
A10: D4 | B10: Power | C10: LED | E10: Light emitting diode
A11: F1 | B11: Power | C11: Polyfuse | E11: Resettable fuse, polymeric positive temperature coefficient
A12: F2 | B12: Power | C12: Polyfuse | E12: Resettable fuse, polymeric positive temperature coefficient
A13: J1 | B13: Power | C13: Conn_01x02_Socket | E13: Generic connector, single row, 01x02, script generated
A14: L1 | B14: Power | C14: 1 uH | E14: Inductor, small symbol
A15: L2 | B15: Power | C15: 2.2 uH | E15: Inductor, small symbol
A16: Q1 | B16: Power | C16: PMOS | E16: P-MOSFET transistor, drain/source/gate
A17: R1 | B17: Power | C17: 182 Kohm | E17: Resistor, small US symbol
A18: R2 | B18: Power | C18: 24.9 Kohm | E18: Resistor, small US symbol
A19: R3 | B19: Power | C19: 16.9 Kohm | E19: Resistor, small US symbol
A20: R4 | B20: Power | C20: 10 Kohm | E20: Resistor, small US symbol
... A24: R8 | B24: Power | C24: 100 Kohm | E24: Resistor, small US symbol
A25: U1 | B25: Power | C25: ~
A26: U2 | B26: Power | C26: ~
A27: C14 | B27: Ethernet | C27: 0.1 uF | E27: Unpolarized capacitor, small symbol
A28: C15 | B28: Ethernet | C28: 0.1 uF | E28: Unpolarized capacitor, small symbol
A29: C16 | B29: Ethernet | C29: 0.1 uF | E29: Unpolarized capacitor, small symbol
A30: C17 | B30: Ethernet | C30: 1 uF | E30: Unpolarized capacitor, small symbol
A31: C18 | B31: Ethernet | C31: 0.1 uF | E31: Unpolarized capacitor, small symbol
A32: C19 | B32: Ethernet | C32: 1 uF | E32: Unpolarized capacitor, small symbol
A33: DSC1004 | B33: Ethernet | C33: 50 MHz oscillator | D33: Oscillator:Oscillator_SMD_SeikoEpson_SG8002CA-4Pin_7.0x5.0mm | E33: CMOS Clock Oscillator 2.5 to 50 MHz
A34: J4 | B34: Ethernet | C34: RJ45_Amphenol_RJMG1BD3B8K1ANR | D34: Connector_RJ:RJ45_Amphenol_RJMG1BD3B8K1ANR | E34: 1 Port RJ45 Magjack Connector Through Hole 10/100 Base-T, AutoMDIX
A35: R13 | B35: Ethernet | C35: 100 Kohms | E35: Resistor, small US symbol
A36: R14 | B36: Ethernet | C36: 12.1 Kohms 1% tol | E36: Resistor, small US symbol
A37: R15 | B37: Ethernet | C37: 120 ohms | E37: Resistor, small US symbol
A38: R16 | B38: Ethernet | C38: 120 ohms | E38: Resistor, small US symbol
A39: R17 | B39: Ethernet | C39: 10 Kohms | E39: Resistor, small US symbol
A40: R18 | B40: Ethernet | C40: 10 Kohms | E40: Resistor, small US symbol
A41: SW3 | B41: Ethernet | C41: SW_Push | E41: Push button switch, generic, two pins
A42: U7 | B42: Ethernet | C42: LAN8720A | D42: Package_DFN_QFN:VQFN-24-1EP_4x4mm_P0.5mm_EP2.5x2.5mm_ThermalVias | E42: LAN8720 Ethernet PHY with RMII interface, QFN-24
A43: BOOT_CTRL1 | B43: ESP32 | C43: NMOS | E43: N-MOSFET transistor, drain/source/gate
...
